TESTS WITH ERRORS 
test16_DFS_8Puzzle_02 (gradingtests.UnitTests)
Traceback (most recent call last):
  File "C:\Users\kille\academics\automatedgradingapp\app\testing\uninformed-solvers\gradingtests.py", line 52, in runPlayXSteps
    results = self.pool.apply_async(self.playXSteps, [solver, plays]).get(timeout)
  File "C:\Program Files\Python37\lib\multiprocessing\pool.py", line 679, in get
    raise TimeoutError
multiprocessing.context.TimeoutError

During handling of the above exception, another exception occurred:

Traceback (most recent call last):
  File "C:\Users\kille\academics\automatedgradingapp\app\testing\uninformed-solvers\gradingtests.py", line 352, in test16_DFS_8Puzzle_02
    [30, ((8, 1, -1), (7, 2, 3), (6, 5, 4))],
  File "C:\Users\kille\academics\automatedgradingapp\app\testing\uninformed-solvers\gradingtests.py", line 57, in runPlayXSteps
    raise Exception("Timed out: %s" % inspect.stack()[1][3])
Exception: Timed out: test16_DFS_8Puzzle_02

test17_DFS_8Puzzle_03 (gradingtests.UnitTests)
Traceback (most recent call last):
  File "C:\Users\kille\academics\automatedgradingapp\app\testing\uninformed-solvers\gradingtests.py", line 52, in runPlayXSteps
    results = self.pool.apply_async(self.playXSteps, [solver, plays]).get(timeout)
  File "C:\Program Files\Python37\lib\multiprocessing\pool.py", line 679, in get
    raise TimeoutError
multiprocessing.context.TimeoutError

During handling of the above exception, another exception occurred:

Traceback (most recent call last):
  File "C:\Users\kille\academics\automatedgradingapp\app\testing\uninformed-solvers\gradingtests.py", line 371, in test17_DFS_8Puzzle_03
    [8, ((8, 3, 4), (2, -1, 1), (7, 6, 5))],
  File "C:\Users\kille\academics\automatedgradingapp\app\testing\uninformed-solvers\gradingtests.py", line 57, in runPlayXSteps
    raise Exception("Timed out: %s" % inspect.stack()[1][3])
Exception: Timed out: test17_DFS_8Puzzle_03

test20_BFS_8Puzzle_03 (gradingtests.UnitTests)
Traceback (most recent call last):
  File "C:\Users\kille\academics\automatedgradingapp\app\testing\uninformed-solvers\gradingtests.py", line 52, in runPlayXSteps
    results = self.pool.apply_async(self.playXSteps, [solver, plays]).get(timeout)
  File "C:\Program Files\Python37\lib\multiprocessing\pool.py", line 679, in get
    raise TimeoutError
multiprocessing.context.TimeoutError

During handling of the above exception, another exception occurred:

Traceback (most recent call last):
  File "C:\Users\kille\academics\automatedgradingapp\app\testing\uninformed-solvers\gradingtests.py", line 428, in test20_BFS_8Puzzle_03
    [7, ((1, 2, -1), (8, 4, 3), (7, 6, 5))],
  File "C:\Users\kille\academics\automatedgradingapp\app\testing\uninformed-solvers\gradingtests.py", line 57, in runPlayXSteps
    raise Exception("Timed out: %s" % inspect.stack()[1][3])
Exception: Timed out: test20_BFS_8Puzzle_03

-------------------------------
TESTS FAILED  
test07_GM_8Puzzle_03 (gradingtests.UnitTests)
Traceback (most recent call last):
  File "C:\Users\kille\academics\automatedgradingapp\app\testing\uninformed-solvers\gradingtests.py", line 175, in test07_GM_8Puzzle_03
    self.assertEqual(p8.getGameState(), ((5,1,4), (6,-1,8), (7,3,2)))
AssertionError: Tuples differ: ((5, 4, -1), (6, 1, 8), (7, 3, 2)) != ((5, 1, 4), (6, -1, 8), (7, 3, 2))

First differing element 0:
(5, 4, -1)
(5, 1, 4)

- ((5, 4, -1), (6, 1, 8), (7, 3, 2))
?       ----

+ ((5, 1, 4), (6, -1, 8), (7, 3, 2))
?      +++        +


test08_GM_8Puzzle_04 (gradingtests.UnitTests)
Traceback (most recent call last):
  File "C:\Users\kille\academics\automatedgradingapp\app\testing\uninformed-solvers\gradingtests.py", line 200, in test08_GM_8Puzzle_04
    self.assertEqual(p8.getGameState(), ((1,-1,3,),(8,2,4),(7,6,5)))
AssertionError: Tuples differ: ((1, 2, 3), (8, 2, 4), (7, 6, 5)) != ((1, -1, 3), (8, 2, 4), (7, 6, 5))

First differing element 0:
(1, 2, 3)
(1, -1, 3)

- ((1, 2, 3), (8, 2, 4), (7, 6, 5))
?      ^

+ ((1, -1, 3), (8, 2, 4), (7, 6, 5))
?      ^^


-------------------------------
TESTS SKIPPED 
-------------------------------
